Traceback (most recent call last):
  File "forecast.py", line 37, in <module>
    del forecast_data['Time']
  File "/Users/danylokaras/anaconda2/lib/python2.7/site-packages/pandas/core/generic.py", line 2096, in __delitem__
    self._data.delete(key)
  File "/Users/danylokaras/anaconda2/lib/python2.7/site-packages/pandas/core/internals.py", line 3902, in delete
    indexer = self.items.get_loc(item)
  File "/Users/danylokaras/anaconda2/lib/python2.7/site-packages/pandas/core/indexes/base.py", line 2527, in get_loc
    return self._engine.get_loc(self._maybe_cast_indexer(key))
  File "pandas/_libs/index.pyx", line 117, in pandas._libs.index.IndexEngine.get_loc
  File "pandas/_libs/index.pyx", line 139, in pandas._libs.index.IndexEngine.get_loc
  File "pandas/_libs/hashtable_class_helper.pxi", line 1265, in pandas._libs.hashtable.PyObjectHashTable.get_item
  File "pandas/_libs/hashtable_class_helper.pxi", line 1273, in pandas._libs.hashtable.PyObjectHashTable.get_item
KeyError: 'Time'
